<?xml version="1.0" encoding="utf-8"?>
<robot name="gripper">
  <material name="gripper_white">
    <color rgba="1 1 1 1"/>
  </material>
  <material name="gripper_gray">
    <color rgba="0.4 0.4 0.4 1"/>
  </material>
  <material name="silver">
    <color rgba="0.5 0.5 0.5 1"/>
  </material>

  <link name="gripper_base">
  	<inertial>
      <origin rpy="0 0 0" xyz="0 0 0.0"/>
       <mass value=".81"/>
       <inertia ixx="0.1" ixy="0" ixz="0" iyy="0.1" iyz="0" izz="0.1"/>
    </inertial>
    <visual>
      <geometry>
        <mesh filename="package://realsense2_camera/objs/gripper.obj"/>
      </geometry>
      <material name="gripper_white"/>
    </visual>
    <collision>
      <geometry>
        <mesh filename="package://realsense2_camera/objs/gripper.obj"/>
      </geometry>
      <material name="gripper_white"/>
    </collision>
  </link>

  <link name="gripper_left">
  	<inertial>
      <origin rpy="0 0 0" xyz="0 0 0.0"/>
       <mass value=".81"/>
       <inertia ixx="0.1" ixy="0" ixz="0" iyy="0.1" iyz="0" izz="0.1"/>
    </inertial>
    <visual>
      <geometry>
        <mesh filename="package://realsense2_camera/objs/left_finger.obj"/>
      </geometry>
      <material name="gripper_gray"/>
    </visual>
    <collision>
      <geometry>
        <mesh filename="package://realsense2_camera/objs/left_finger.obj"/>
      </geometry>
      <material name="gripper_gray"/>
    </collision>
  </link>

  <link name="gripper_right">
  	<inertial>
      <origin rpy="0 0 0" xyz="0 0 0.0"/>
       <mass value=".81"/>
       <inertia ixx="0.1" ixy="0" ixz="0" iyy="0.1" iyz="0" izz="0.1"/>
    </inertial>
    <visual>
      <geometry>
        <mesh filename="package://realsense2_camera/objs/right_finger.obj"/>
      </geometry>
      <material name="gripper_gray"/>
    </visual>
    <collision>
      <geometry>
        <mesh filename="package://realsense2_camera/objs/right_finger.obj"/>
      </geometry>
      <material name="gripper_gray"/>
    </collision>
  </link>


  <joint name="finger_joint_left" type="prismatic">
    <parent link="gripper_base"/>
    <child link="gripper_left"/>
    <origin rpy="0 0 0" xyz="0 0 0.0"/>
    <axis xyz="-1 0 0"/>
    <limit effort="20" lower="0.0" upper="0.05" velocity="0.2"/>
  </joint>

  <joint name="finger_joint_right" type="prismatic">
    <parent link="gripper_base"/>
    <child link="gripper_right"/>
    <origin rpy="0 0 0" xyz="0 0 0.0"/>
    <axis xyz="1 0 0"/>
    <limit effort="20" lower="0.0" upper="0.05" velocity="0.2"/>
    <mimic joint="finger_joint_left"/>
  </joint>

  <link name="ft_peeler">
  	<inertial>
      <origin rpy="0 0 0" xyz="0 0 0.0"/>
       <mass value=".81"/>
       <inertia ixx="0.1" ixy="0" ixz="0" iyy="0.1" iyz="0" izz="0.1"/>
    </inertial>
    <visual>
      <geometry>
        <mesh filename="package://realsense2_camera/objs/peeler.obj"/>
      </geometry>
      <material name="gripper_gray"/>
    </visual>
    <collision>
      <geometry>
        <mesh filename="package://realsense2_camera/objs/peeler.obj"/>
      </geometry>
      <material name="gripper_gray"/>
    </collision>
  </link>

  <joint name="ft_peeler_joint" type="floating">
    <parent link="gripper_base"/>
    <child link="ft_peeler"/>
    <origin rpy="0 0 0" xyz="0 0 0.0"/>
    <limit effort="20" lower="-2" upper="2" velocity="0.2"/>
  </joint>
</robot>